Workbook

Sheet Aid recipients
A1: ﻿Country | B1: Another Beneficiary Member State | C1: Aid Measure Title | D1: Aid Measure Title [EN] | E1: SA.Number | F1: Ref-no. | G1: National ID | H1: Name of the beneficiary | I1: Name of the beneficiary [EN] | J1: Beneficiary Type | K1: Region | L1: Sector (NACE) | M1: Aid Instrument | N1: Objectives of the Aid | O1: Aid element, expressed as full amount | P1: Currency | Q1: Date of granting | R1: Granting Authority Name | S1: Granting Authority Name [EN] | T1: Published Date
A2: Latvia | B2: Latvia | C2: Atbalsts ieguldījumiem ražošanas telpu un infrastruktūras izveidei vai rekonstrukcijai | D2: Aid for investments for the construction or reconstruction of industrial premises and infrastructure | E2: SA.45422 | F2: TM-10001476 | G2: 50003428031 | H2: Mārupes Metālmeistars | I2: Marupes metālmeistars | J2: Small and medium-sized entreprises | K2: Latvija | L2: Manufacture of other fabricated metal products n.e.c. | M2: Direct grant/ Interest rate subsidy | N2: Regional aid - investment aid (Art. 14) - Scheme | O2: 799480.74 | P2: EUR | Q2: 42677 | R2: Centrālā finanšu un līgumu aģentūra | S2: Central Finance and Contracting Agency | T2: 42724
A3: Latvia | B3: Latvia | C3: Atbalsts ieguldījumiem ražošanas telpu un infrastruktūras izveidei vai rekonstrukcijai | D3: Aid for investments for the construction or reconstruction of industrial premises and infrastructure | E3: SA.45422 | F3: TM-10001481 | G3: 50103186141 | H3: TECNOPALI NORTH EUROPE | I3: TECNOPALI NORTH EUROPE | J3: Small and medium-sized entreprises | K3: Latvija | L3: Manufacture of metal structures and parts of structures | M3: Direct grant/ Interest rate subsidy | N3: Regional aid - investment aid (Art. 14) - Scheme | O3: 833058.47 | P3: EUR | Q3: 42677 | R3: Centrālā finanšu un līgumu aģentūra | S3: Central Finance and Contracting Agency | T3: 42724
A4: Latvia | B4: Latvia | C4: Atbalsts ieguldījumiem ražošanas telpu un infrastruktūras izveidei vai rekonstrukcijai | D4: Aid for investments for the construction or reconstruction of industrial premises and infrastructure | E4: SA.45422 | F4: TM-10001472 | G4: 90000284085 | H4: Ventspils Brīvostas pārvalde | I4: Ventspils Free Port Authority | J4: Only large enterprises | K4: Latvija | L4: Service activities incidental to water transportation | M4: Direct grant/ Interest rate subsidy | N4: Regional aid - investment aid (Art. 14) - Scheme | O4: 1165802.83 | P4: EUR | Q4: 42677 | R4: Centrālā finanšu un līgumu aģentūra | S4: Central Finance and Contracting Agency | T4: 42724
A5: Latvia | B5: Latvia | C5: Atbalsts ieguldījumiem ražošanas telpu un infrastruktūras izveidei vai rekonstrukcijai | D5: Aid for investments for the construction or reconstruction of industrial premises and infrastructure | E5: SA.45422 | F5: TM-10001480 | G5: 40003294211 | H5: Tukuma Piens | I5: Tukums Milk | J5: Small and medium-sized entreprises | K5: Latvija | L5: Operation of dairies and cheese making | M5: Direct grant/ Interest rate subsidy | N5: Regional aid - investment aid (Art. 14) - Scheme | O5: 964778.3 | P5: EUR | Q5: 42706 | R5: Centrālā finanšu un līgumu aģentūra | S5: Central Finance and Contracting Agency | T5: 42724
A6: Latvia | B6: Latvia | C6: Atbalsts ieguldījumiem ražošanas telpu un infrastruktūras izveidei vai rekonstrukcijai | D6: Aid for investments for the construction or reconstruction of industrial premises and infrastructure | E6: SA.45422 | F6: TM-10001470 | G6: 42103073886 | H6: Vecās Ostmalas Biznesa Parks | I6: Old Ostmalas Business Parks | J6: Small and medium-sized entreprises | K6: Latvija | L6: Rental and operating of own or leased real estate | M6: Direct grant/ Interest rate subsidy | N6: Regional aid - investment aid (Art. 14) - Scheme | O6: 582594.57 | P6: EUR | Q6: 42706 | R6: Centrālā finanšu un līgumu aģentūra | S6: Central Finance and Contracting Agency | T6: 42724
A7: Latvia | B7: Latvia | C7: Atbalsts ieguldījumiem ražošanas telpu un infrastruktūras izveidei vai rekonstrukcijai | D7: Aid for investments for the construction or reconstruction of industrial premises and infrastructure | E7: SA.45422 | F7: TM-10001479 | G7: 40203003707 | H7: TRAPI | I7: LADDERS | J7: Small and medium-sized entreprises | K7: Latvija | L7: Rental and operating of own or leased real estate | M7: Direct grant/ Interest rate subsidy | N7: Regional aid - investment aid (Art. 14) - Scheme | O7: 1166000 | P7: EUR | Q7: 42706 | R7: Centrālā finanšu un līgumu aģentūra | S7: Central Finance and Contracting Agency | T7: 42724
A8: Latvia | B8: Latvia | C8: Atbalsts ieguldījumiem ražošanas telpu un infrastruktūras izveidei vai rekonstrukcijai | D8: Aid for investments for the construction or reconstruction of industrial premises and infrastructure | E8: SA.45422 | F8: TM-10065234 | G8: 90000284085 | H8: Ventspils Brīvostas pārvalde | I8: Ventspils Free Port Authority | J8: Only large enterprises | K8: Kurzeme | L8: Service activities incidental to water transportation | M8: Direct grant/ Interest rate subsidy | N8: Regional aid - investment aid (Art. 14) - Scheme | O8: 1165839.59 | P8: EUR | Q8: 42731 | R8: Centrālā finanšu un līgumu aģentūra | S8: Central Finance and Contracting Agency | T8: 42912
A9: Latvia | B9: Latvia | C9: Atbalsts ieguldījumiem ražošanas telpu un infrastruktūras izveidei vai rekonstrukcijai | D9: Aid for investments for the construction or reconstruction of industrial premises and infrastructure | E9: SA.45422 | F9: TM-10065240 | G9: 40203006027 | H9: GP TEHNOPARKI | I9: GP TEHNOPARKI | J9: Small and medium-sized entreprises | K9: Pierīga | L9: Rental and operating of own or leased real estate | M9: Direct grant/ Interest rate subsidy | N9: Regional aid - investment aid (Art. 14) - Scheme | O9: 1146555.6 | P9: EUR | Q9: 42731 | R9: Centrālā finanšu un līgumu aģentūra | S9: Central Finance and Contracting Agency | T9: 42912
A10: Latvia | B10: Latvia | C10: Atbalsts ieguldījumiem ražošanas telpu un infrastruktūras izveidei vai rekonstrukcijai | D10: Aid for investments for the construction or reconstruction of industrial premises and infrastructure | E10: SA.45422 | F10: TM-10065241 | G10: 40103748266 | H10: NTC INVESTĪCIJAS | I10: THE NTC INVESTMENT | J10: Small and medium-sized entreprises | K10: Vidzeme | L10: Rental and operating of own or leased real estate | M10: Direct grant/ Interest rate subsidy | N10: Regional aid - investment aid (Art. 14) - Scheme | O10: 628631.66 | P10: EUR | Q10: 42731 | R10: Centrālā finanšu un līgumu aģentūra | S10: Central Finance and Contracting Agency | T10: 42912
A11: Latvia | B11: Latvia | C11: Atbalsts ieguldījumiem ražošanas telpu un infrastruktūras izveidei vai rekonstrukcijai | D11: Aid for investments for the construction or reconstruction of industrial premises and infrastructure | E11: SA.45422 | F11: TM-10065236 | G11: 90000284085 | H11: Ventspils Brīvostas pārvalde | I11: Ventspils Free Port Authority | J11: Only large enterprises | K11: Kurzeme | L11: Service activities incidental to water transportation | M11: Direct grant/ Interest rate subsidy | N11: Regional aid - investment aid (Art. 14) - Scheme | O11: 1165752.18 | P11: EUR | Q11: 42731 | R11: Centrālā finanšu un līgumu aģentūra | S11: Central Finance and Contracting Agency | T11: 42912
A12: Latvia | B12: Latvia | C12: Atbalsts ieguldījumiem ražošanas telpu un infrastruktūras izveidei vai rekonstrukcijai | D12: Aid for investments for the construction or reconstruction of industrial premises and infrastructure | E12: SA.45422 | F12: TM-10065239 | G12: 45103000023 | H12: TENAX | I12: TENAX | J12: Small and medium-sized entreprises | K12: Zemgale | L12: Rental and operating of own or leased real estate | M12: Direct grant/ Interest rate subsidy | N12: Regional aid - investment aid (Art. 14) - Scheme | O12: 1166000 | P12: EUR | Q12: 42731 | R12: Centrālā finanšu un līgumu aģentūra | S12: Central Finance and Contracting Agency | T12: 42912
A13: Latvia | B13: Latvia | C13: Atbalsts ieguldījumiem ražošanas telpu un infrastruktūras izveidei vai rekonstrukcijai | D13: Aid for investments for the construction or reconstruction of industrial premises and infrastructure | E13: SA.45422 | F13: TM-10065238 | G13: 40103563278 | H13: IT INTERNATIONAL | I13: IN INTERNATIONAL | J13: Small and medium-sized entreprises | K13: Latgale | L13: Sawmilling and planing of wood | M13: Direct grant/ Interest rate subsidy | N13: Regional aid - investment aid (Art. 14) - Scheme | O13: 681010.03 | P13: EUR | Q13: 42731 | R13: Centrālā finanšu un līgumu aģentūra | S13: Central Finance and Contracting Agency | T13: 42912
... A15: Latvia | B15: Latvia | C15: Atbalsts ieguldījumiem ražošanas telpu un infrastruktūras izveidei vai rekonstrukcijai | D15: Aid for investments for the construction or reconstruction of industrial premises and infrastructure | E15: SA.45422 | F15: TM-10065266 | G15: 40003822806 | H15: Lyngson | I15: Lyngson | J15: Small and medium-sized entreprises | K15: Pierīga | L15: Manufacture of central heating radiators and boilers | M15: Direct grant/ Interest rate subsidy | N15: Regional aid - investment aid (Art. 14) - Scheme | O15: 798750 | P15: EUR | Q15: 42760 | R15: Centrālā finanšu un līgumu aģentūra | S15: Central Finance and Contracting Agency | T15: 42913
A16: Latvia | B16: Latvia | C16: Atbalsts ieguldījumiem ražošanas telpu un infrastruktūras izveidei vai rekonstrukcijai | D16: Aid for investments for the construction or reconstruction of industrial premises and infrastructure | E16: SA.45422 | F16: TM-10065261 | G16: 40003199078 | H16: Piebalgas | I16: Piebalgas | J16: Small and medium-sized entreprises | K16: Zemgale | L16: Sawmilling and planing of wood | M16: Direct grant/ Interest rate subsidy | N16: Regional aid - investment aid (Art. 14) - Scheme | O16: 512510 | P16: EUR | Q16: 42760 | R16: Centrālā finanšu un līgumu aģentūra | S16: Central Finance and Contracting Agency | T16: 42913
A17: Latvia | B17: Latvia | C17: Atbalsts ieguldījumiem ražošanas telpu un infrastruktūras izveidei vai rekonstrukcijai | D17: Aid for investments for the construction or reconstruction of industrial premises and infrastructure | E17: SA.45422 | F17: TM-10065265 | G17: 40003479924 | H17: Kronus | I17: Kronus | J17: Small and medium-sized entreprises | K17: Pierīga | L17: Manufacture of wooden containers | M17: Direct grant/ Interest rate subsidy | N17: Regional aid - investment aid (Art. 14) - Scheme | O17: 810306 | P17: EUR | Q17: 42760 | R17: Centrālā finanšu un līgumu aģentūra | S17: Central Finance and Contracting Agency | T17: 42913
A18: Latvia | B18: Latvia | C18: Atbalsts ieguldījumiem ražošanas telpu un infrastruktūras izveidei vai rekonstrukcijai | D18: Aid for investments for the construction or reconstruction of industrial premises and infrastructure | E18: SA.45422 | F18: TM-10065262 | G18: 42103060434 | H18: NPK Expert | I18: NPK Expert | J18: Small and medium-sized entreprises | K18: Kurzeme | L18: Manufacture of fertilisers and nitrogen compounds | M18: Direct grant/ Interest rate subsidy | N18: Regional aid - investment aid (Art. 14) - Scheme | O18: 627697 | P18: EUR | Q18: 42769 | R18: Centrālā finanšu un līgumu aģentūra | S18: Central Finance and Contracting Agency | T18: 42913
A19: Latvia | B19: Latvia | C19: Atbalsts ieguldījumiem ražošanas telpu un infrastruktūras izveidei vai rekonstrukcijai | D19: Aid for investments for the construction or reconstruction of industrial premises and infrastructure | E19: SA.45422 | F19: TM-10065264 | G19: 40003919987 | H19: EcoLead | I19: EcoLead | J19: Small and medium-sized entreprises | K19: Zemgale | L19: Lead, zinc and tin production | M19: Direct grant/ Interest rate subsidy | N19: Regional aid - investment aid (Art. 14) - Scheme | O19: 560700 | P19: EUR | Q19: 42769 | R19: Centrālā finanšu un līgumu aģentūra | S19: Central Finance and Contracting Agency | T19: 42913
A20: Latvia | B20: Latvia | C20: Atbalsts ieguldījumiem ražošanas telpu un infrastruktūras izveidei vai rekonstrukcijai | D20: Aid for investments for the construction or reconstruction of industrial premises and infrastructure | E20: SA.45422 | F20: TM-10080807 | G20: 40103702152 | H20: Carbon energy systems | I20: Carbon energy systems | J20: Small and medium-sized entreprises | K20: Vidzeme | L20: Manufacture of other organic basic chemicals | M20: Direct grant/ Interest rate subsidy | N20: Regional aid - investment aid (Art. 14) - Scheme | O20: 623040.77 | P20: EUR | Q20: 42993 | R20: Centrālā finanšu un līgumu aģentūra | S20: Central Finance and Contracting Agency | T20: 43007
A21: Latvia | B21: Latvia | C21: Atbalsts ieguldījumiem ražošanas telpu un infrastruktūras izveidei vai rekonstrukcijai | D21: Aid for investments for the construction or reconstruction of industrial premises and infrastructure | E21: SA.45422 | F21: TM-10171220 | G21: 45403003160 | H21: JĒKABPILS PMK | I21: JĒKABPILS PNK | J21: Small and medium-sized entreprises | K21: Latvija | L21: Construction of residential and non-residential buildings | M21: Direct grant/ Interest rate subsidy | N21: Regional aid - investment aid (Art. 14) - Scheme | O21: 735300 | P21: EUR | Q21: 43707 | R21: Centrālā finanšu un līgumu aģentūra | S21: Central Finance and Contracting Agency | T21: 43733
A22: Latvia | B22: Latvia | C22: Atbalsts ieguldījumiem ražošanas telpu un infrastruktūras izveidei vai rekonstrukcijai | D22: Aid for investments for the construction or reconstruction of industrial premises and infrastructure | E22: SA.45422 | F22: TM-10171221 | G22: 40203021261 | H22: AmberBirch | I22: AmberBirch | J22: Small and medium-sized entreprises | K22: Latvija | L22: Manufacture of veneer sheets and wood-based panels | M22: Direct grant/ Interest rate subsidy | N22: Regional aid - investment aid (Art. 14) - Scheme | O22: 1500000 | P22: EUR | Q22: 43720 | R22: Centrālā finanšu un līgumu aģentūra | S22: Central Finance and Contracting Agency | T22: 43733
A23: Latvia | B23: Latvia | C23: Atbalsts ieguldījumiem ražošanas telpu un infrastruktūras izveidei vai rekonstrukcijai | D23: Aid for investments for the construction or reconstruction of industrial premises and infrastructure | E23: SA.45422 | F23: TM-10182047 | G23: 40003752458 | H23: VALMIERMUIŽAS ALUS | I23: VALMIERMUNIIC BEER | J23: Small and medium-sized entreprises | K23: Latvija | L23: Manufacture of beer | M23: Direct grant/ Interest rate subsidy | N23: Regional aid - investment aid (Art. 14) - Scheme | O23: 1307155 | P23: EUR | Q23: 43734 | R23: Centrālā finanšu un līgumu aģentūra | S23: Central Finance and Contracting Agency | T23: 43845
A24: Latvia | B24: Latvia | C24: Atbalsts ieguldījumiem ražošanas telpu un infrastruktūras izveidei vai rekonstrukcijai | D24: Aid for investments for the construction or reconstruction of industrial premises and infrastructure | E24: SA.45422 | F24: TM-10182086 | G24: 42103021136 | H24: PUMAC LIEPAJA | I24: PUMAC LAYER | J24: Small and medium-sized entreprises | K24: Latvija | L24: Rental and operating of own or leased real estate | M24: Direct grant/ Interest rate subsidy | N24: Regional aid - investment aid (Art. 14) - Scheme | O24: 1500000 | P24: EUR | Q24: 43734 | R24: Centrālā finanšu un līgumu aģentūra | S24: Central Finance and Contracting Agency | T24: 43845
A25: Latvia | B25: Latvia | C25: Atbalsts ieguldījumiem ražošanas telpu un infrastruktūras izveidei vai rekonstrukcijai | D25: Aid for investments for the construction or reconstruction of industrial premises and infrastructure | E25: SA.45422 | F25: TM-10182088 | G25: 45403042702 | H25: CEWOOD | I25: CEWOOD | J25: Small and medium-sized entreprises | K25: Latvija | L25: Manufacture of fibre cement | M25: Direct grant/ Interest rate subsidy | N25: Regional aid - investment aid (Art. 14) - Scheme | O25: 1124985.15 | P25: EUR | Q25: 43759 | R25: Centrālā finanšu un līgumu aģentūra | S25: Central Finance and Contracting Agency | T25: 43845
A26: Latvia | B26: Latvia | C26: Atbalsts ieguldījumiem ražošanas telpu un infrastruktūras izveidei vai rekonstrukcijai | D26: Aid for investments for the construction or reconstruction of industrial premises and infrastructure | E26: SA.45422 | F26: TM-10182089 | G26: 54103005451 | H26: VUDLANDE | I26: ﻿VUDLANDE | J26: Small and medium-sized entreprises | K26: Latvija | L26: Sawmilling and planing of wood | M26: Direct grant/ Interest rate subsidy | N26: Regional aid - investment aid (Art. 14) - Scheme | O26: 919509.28 | P26: EUR | Q26: 43759 | R26: Centrālā finanšu un līgumu aģentūra | S26: Central Finance and Contracting Agency | T26: 43845
A27: Latvia | B27: Latvia | C27: Atbalsts ieguldījumiem ražošanas telpu un infrastruktūras izveidei vai rekonstrukcijai | D27: Aid for investments for the construction or reconstruction of industrial premises and infrastructure | E27: SA.45422 | F27: TM-10182090 | G27: 40103299681 | H27: Artex Latvia | I27: Artex Latvia | J27: Small and medium-sized entreprises | K27: Latvija | L27: Manufacture of made-up textile articles, except apparel | M27: Direct grant/ Interest rate subsidy | N27: Regional aid - investment aid (Art. 14) - Scheme | O27: 769624.54 | P27: EUR | Q27: 43766 | R27: Centrālā finanšu un līgumu aģentūra | S27: Central Finance and Contracting Agency | T27: 43845
A28: Latvia | B28: Latvia | C28: Atbalsts ieguldījumiem ražošanas telpu un infrastruktūras izveidei vai rekonstrukcijai | D28: Aid for investments for the construction or reconstruction of industrial premises and infrastructure | E28: SA.45422 | F28: TM-10195045 | G28: 40103318408 | H28: SFM Latvia | I28: SFM Latvia | J28: Small and medium-sized entreprises | K28: Latvija | L28: Manufacture of metal structures and parts of structures | M28: Direct grant/ Interest rate subsidy | N28: Regional aid - investment aid (Art. 14) - Scheme | O28: 1175655.96 | P28: EUR | Q28: 43812 | R28: Centrālā finanšu un līgumu aģentūra | S28: Central Finance and Contracting Agency | T28: 43924
... A37: Latvia | B37: Latvia | C37: Atbalsts ieguldījumiem ražošanas telpu un infrastruktūras izveidei vai rekonstrukcijai | D37: Aid for investments for the construction or reconstruction of industrial premises and infrastructure | E37: SA.45422 | F37: TM-10269935 | G37: 40103590897 | H37: VIZULO | I37: MR VIZULO | J37: Small and medium-sized entreprises | K37: Latvija | L37: Manufacture of electric lighting equipment | M37: Direct grant/ Interest rate subsidy | N37: Regional aid - investment aid (Art. 14) - Scheme | O37: 1096914.58 | P37: EUR | Q37: 44225 | R37: Centrālā finanšu un līgumu aģentūra | S37: Central Finance and Contracting Agency | T37: 44281
N39: total | O39: =O2+O3+O4+O5+O6+O7+O8+O9+O10+O11+O12+O13+O14+O15+O16+O17+O18+O19+O20+O21+O22+O23+O24+O25+O26+O27+O28+O29+O30+O31+O32+O33+O34+O35+O36+O37 -> 35761225
O40: 35761225
Q42: Cost per job created
N43: employee dif in T1 | O43: =Employees!AE31-Employees!AD31 -> 97 | Q43: =O39/O43 -> 368672.42
O44: =Employees!AF31-Employees!AD31 -> 398 | Q44: =O39/O44 -> 89852.324
O45: =Employees!AG31-Employees!AD31 -> 513 | Q45: =O39/O45 -> 69709.99

Sheet Firm list
A1: ID | B1: Name | C1: NACE | D1: Website | E1: Notes | F1: Employees | G1: Tangible assets | H1: Yearly sales | I1: Investment | J1: Wages | K1: Total available
A2: 1 | B2: Mārupes Metālmeistars | C2: 25.4 | D2: https://www.metalmaster.lv/eng | E2: - | F2: =Employees!O2 -> Yes | G2: ='Tangible assets'!O2 -> Yes | H2: ='Yearly Sales'!O2 -> Yes | I2: ='Investment (capex)'!O2 -> Yes | J2: ='Wages salaries'!O2 -> Yes | K2: =COUNTIF(F2:J2,"yes") -> 5
A3: =A2+1 -> 2 | B3: TECNOPALI NORTH EUROPE | C3: 25.11 | D3: https://www.tecnopali.lv/ | E3: - | F3: =Employees!O3 -> Yes | G3: ='Tangible assets'!O3 -> Yes | H3: ='Yearly Sales'!O3 -> Yes | I3: ='Investment (capex)'!O3 -> No | J3: ='Wages salaries'!O3 -> Yes | K3: =COUNTIF(F3:J3,"yes") -> 4
A4: =A3+1 -> 3 | B4: Ventspils Brīvostas pārvalde | C4: 50.2 | D4: https://www.portofventspils.lv/lv/brivostas-parvalde/ | E4: No employee numbers in 2017-2013 | F4: =Employees!O4 -> No | G4: ='Tangible assets'!O4 -> Yes | H4: ='Yearly Sales'!O4 -> Yes | I4: ='Investment (capex)'!O4 -> No | J4: ='Wages salaries'!O4 -> No | K4: =COUNTIF(F4:J4,"yes") -> 2
A5: =A4+1 -> 4 | B5: Tukuma Piens | C5: 10.51 | D5: https://baltais.lv/?lang=en | E5: - | F5: =Employees!O5 -> Yes | G5: ='Tangible assets'!O5 -> Yes | H5: ='Yearly Sales'!O5 -> Yes | I5: ='Investment (capex)'!O5 -> Yes | J5: ='Wages salaries'!O5 -> Yes | K5: =COUNTIF(F5:J5,"yes") -> 5
A6: =A5+1 -> 5 | B6: Vecās Ostmalas Biznesa Parks | C6: 68.2 | D6: https://vobp.lv/ | E6: Almost no employees | F6: =Employees!O6 -> Yes | G6: ='Tangible assets'!O6 -> No | H6: ='Yearly Sales'!O6 -> No | I6: ='Investment (capex)'!O6 -> No | J6: ='Wages salaries'!O6 -> No | K6: =COUNTIF(F6:J6,"yes") -> 1
A7: =A6+1 -> 6 | B7: TRAPI | C7: 41.2 | D7: NA | E7: Almost no employees | F7: =Employees!O7 -> No | G7: ='Tangible assets'!O7 -> No | H7: ='Yearly Sales'!O7 -> No | I7: ='Investment (capex)'!O7 -> No | J7: ='Wages salaries'!O7 -> No | K7: =COUNTIF(F7:J7,"yes") -> 0
A8: =A7+1 -> 7 | B8: GP TEHNOPARKI | C8: 68.2 | D8: NA | E8: Almost no employees | F8: =Employees!O8 -> No | G8: ='Tangible assets'!O8 -> No | H8: ='Yearly Sales'!O8 -> No | I8: ='Investment (capex)'!O8 -> No | J8: ='Wages salaries'!O8 -> No | K8: =COUNTIF(F8:J8,"yes") -> 0
A9: =A8+1 -> 8 | B9: NTC INVESTĪCIJAS | C9: 68.2 | D9: NA | E9: Reports zero employees | F9: =Employees!O9 -> No | G9: ='Tangible assets'!O9 -> Yes | H9: ='Yearly Sales'!O9 -> Yes | I9: ='Investment (capex)'!O9 -> No | J9: ='Wages salaries'!O9 -> No | K9: =COUNTIF(F9:J9,"yes") -> 2
A10: =A9+1 -> 9 | B10: TENAX | C10: 23.66 | D10: https://tenaxpanel.lv/lv/ | E10: - | F10: =Employees!O10 -> Yes | G10: ='Tangible assets'!O10 -> No | H10: ='Yearly Sales'!O10 -> Yes | I10: ='Investment (capex)'!O10 -> Yes | J10: ='Wages salaries'!O10 -> Yes | K10: =COUNTIF(F10:J10,"yes") -> 4
A11: =A10+1 -> 10 | B11: IT INTERNATIONAL | C11: 62.1 | D11: https://company.lursoft.lv/en/international-it-latvia/41503088322 | E11: Liquidated | F11: =Employees!O11 -> No | G11: ='Tangible assets'!O11 -> No | H11: ='Yearly Sales'!O11 -> No | I11: ='Investment (capex)'!O11 -> No | J11: ='Wages salaries'!O11 -> No | K11: =COUNTIF(F11:J11,"yes") -> 0
A12: =A11+1 -> 11 | B12: iCotton | C12: 20.42 | D12: https://www.icotton.eu/ | E12: - | F12: =Employees!O12 -> Yes | G12: ='Tangible assets'!O12 -> Yes | H12: ='Yearly Sales'!O12 -> Yes | I12: ='Investment (capex)'!O12 -> Yes | J12: ='Wages salaries'!O12 -> Yes | K12: =COUNTIF(F12:J12,"yes") -> 5
A13: =A12+1 -> 12 | B13: Lyngson | C13: 25.21 | D13: https://lyngson.lv/ | E13: - | F13: =Employees!O13 -> Yes | G13: ='Tangible assets'!O13 -> Yes | H13: ='Yearly Sales'!O13 -> Yes | I13: ='Investment (capex)'!O13 -> Yes | J13: ='Wages salaries'!O13 -> Yes | K13: =COUNTIF(F13:J13,"yes") -> 5
A14: =A13+1 -> 13 | B14: Piebalgas | C14: 46.13 or 16.11 | D14: https://www.piebalgas.lv/ | E14: - | F14: =Employees!O14 -> Yes | G14: ='Tangible assets'!O14 -> Yes | H14: ='Yearly Sales'!O14 -> Yes | I14: ='Investment (capex)'!O14 -> No | J14: ='Wages salaries'!O14 -> Yes | K14: =COUNTIF(F14:J14,"yes") -> 4
A15: =A14+1 -> 14 | B15: Kronus | C15: 16.24 or 16.12 | D15: https://www.kronus.eu/lv/ | E15: - | F15: =Employees!O15 -> Yes | G15: ='Tangible assets'!O15 -> Yes | H15: ='Yearly Sales'!O15 -> Yes | I15: ='Investment (capex)'!O15 -> Yes | J15: ='Wages salaries'!O15 -> Yes | K15: =COUNTIF(F15:J15,"yes") -> 5
A16: =A15+1 -> 15 | B16: NPK Expert | C16: 20.15 | D16: https://www.npkexpert.com/ | E16: Collapsed and went bankrupt in late 2019 | F16: =Employees!O16 -> No | G16: ='Tangible assets'!O16 -> No | H16: ='Yearly Sales'!O16 -> No | I16: ='Investment (capex)'!O16 -> No | J16: ='Wages salaries'!O16 -> No | K16: =COUNTIF(F16:J16,"yes") -> 0
A17: =A16+1 -> 16 | B17: EcoLead | C17: 46.87 | D17: https://ecolead.lv/lv/ | E17: - | F17: =Employees!O17 -> Yes | G17: ='Tangible assets'!O17 -> Yes | H17: ='Yearly Sales'!O17 -> No | I17: ='Investment (capex)'!O17 -> No | J17: ='Wages salaries'!O17 -> No | K17: =COUNTIF(F17:J17,"yes") -> 2
A18: =A17+1 -> 17 | B18: Carbon energy systems | C18: 19.1 | D18: NA | E18: - | F18: =Employees!O18 -> Yes | G18: ='Tangible assets'!O18 -> No | H18: ='Yearly Sales'!O18 -> No | I18: ='Investment (capex)'!O18 -> No | J18: ='Wages salaries'!O18 -> No | K18: =COUNTIF(F18:J18,"yes") -> 1
A19: =A18+1 -> 18 | B19: JĒKABPILS PMK | C19: 41 | D19: https://jpmk.lv/ | E19: - | F19: =Employees!O19 -> Yes | G19: ='Tangible assets'!O19 -> Yes | H19: ='Yearly Sales'!O19 -> Yes | I19: ='Investment (capex)'!O19 -> Yes | J19: ='Wages salaries'!O19 -> Yes | K19: =COUNTIF(F19:J19,"yes") -> 5
A20: =A19+1 -> 19 | B20: AmberBirch | C20: 16.21 | D20: https://amberbirch.lv/ | E20: - | F20: =Employees!O20 -> No | G20: ='Tangible assets'!O20 -> Yes | H20: ='Yearly Sales'!O20 -> No | I20: ='Investment (capex)'!O20 -> No | J20: ='Wages salaries'!O20 -> Yes | K20: =COUNTIF(F20:J20,"yes") -> 2
A21: =A20+1 -> 20 | B21: VALMIERMUIŽAS ALUS | C21: 11.05 | D21: https://valmiermuiza.lv/ | E21: - | F21: =Employees!O21 -> Yes | G21: ='Tangible assets'!O21 -> Yes | H21: ='Yearly Sales'!O21 -> Yes | I21: ='Investment (capex)'!O21 -> Yes | J21: ='Wages salaries'!O21 -> Yes | K21: =COUNTIF(F21:J21,"yes") -> 5
A22: =A21+1 -> 21 | B22: PUMAC LIEPAJA | C22: 68.2 | D22: NA | E22: - | F22: =Employees!O22 -> Yes | G22: ='Tangible assets'!O22 -> Yes | H22: ='Yearly Sales'!O22 -> Yes | I22: ='Investment (capex)'!O22 -> No | J22: ='Wages salaries'!O22 -> Yes | K22: =COUNTIF(F22:J22,"yes") -> 4
A23: =A22+1 -> 22 | B23: CEWOOD | C23: 23.65 or 16.10 or 23.65 | D23: https://www.cewood.com/lv | E23: I need 2020 (for year 2019) pieskats because they must have the salary numbers | F23: =Employees!O23 -> Yes | G23: ='Tangible assets'!O23 -> No | H23: ='Yearly Sales'!O23 -> Yes | I23: ='Investment (capex)'!O23 -> No | J23: ='Wages salaries'!O23 -> No | K23: =COUNTIF(F23:J23,"yes") -> 2
A24: =A23+1 -> 23 | B24: VUDLANDE | C24: 16.11 | D24: https://www.vudlande.lv/ | E24: - | F24: =Employees!O24 -> Yes | G24: ='Tangible assets'!O24 -> Yes | H24: ='Yearly Sales'!O24 -> Yes | I24: ='Investment (capex)'!O24 -> Yes | J24: ='Wages salaries'!O24 -> Yes | K24: =COUNTIF(F24:J24,"yes") -> 5
A25: =A24+1 -> 24 | B25: Artex Latvia | C25: 13.92 | D25: https://www.artex.se/smiltene-latvia | E25: - | F25: =Employees!O25 -> Yes | G25: ='Tangible assets'!O25 -> No | H25: ='Yearly Sales'!O25 -> Yes | I25: ='Investment (capex)'!O25 -> No | J25: ='Wages salaries'!O25 -> Yes | K25: =COUNTIF(F25:J25,"yes") -> 3
A26: =A25+1 -> 25 | B26: SFM Latvia | C26: 25.11 | D26: https://sfm.lv/ | E26: Missing wages in 2017 | F26: =Employees!O26 -> Yes | G26: ='Tangible assets'!O26 -> No | H26: ='Yearly Sales'!O26 -> Yes | I26: ='Investment (capex)'!O26 -> No | J26: ='Wages salaries'!O26 -> No | K26: =COUNTIF(F26:J26,"yes") -> 2
A27: =A26+1 -> 26 | B27: EB Liepāja | C27: 68.2 or 41 | D27: NA | E27: Liquidated, was a subsidiary of the STATS Group | F27: =Employees!O27 -> No | G27: ='Tangible assets'!O27 -> No | H27: ='Yearly Sales'!O27 -> No | I27: ='Investment (capex)'!O27 -> No | J27: ='Wages salaries'!O27 -> No | K27: =COUNTIF(F27:J27,"yes") -> 0
A28: =A27+1 -> 27 | B28: Stiga RM | C28: 16.21 or 2.2 | D28: https://stigarm.lv/lv/ | E28: - | F28: =Employees!O28 -> Yes | G28: ='Tangible assets'!O28 -> Yes | H28: ='Yearly Sales'!O28 -> Yes | I28: ='Investment (capex)'!O28 -> Yes | J28: ='Wages salaries'!O28 -> Yes | K28: =COUNTIF(F28:J28,"yes") -> 5
A29: =A28+1 -> 28 | B29: Haugaard Baltic | C29: 31 | D29: https://www.haugaard.eu/ | E29: Operates at a loss, moved to a new factory in 2023-24 | F29: =Employees!O29 -> Yes | G29: ='Tangible assets'!O29 -> No | H29: ='Yearly Sales'!O29 -> Yes | I29: ='Investment (capex)'!O29 -> No | J29: ='Wages salaries'!O29 -> Yes | K29: =COUNTIF(F29:J29,"yes") -> 3
A30: =A29+1 -> 29 | B30: IKTK | C30: 42.13 or 16.28 | D30: https://zazatimber.lv/ | E30: - | F30: =Employees!O30 -> Yes | G30: ='Tangible assets'!O30 -> Yes | H30: ='Yearly Sales'!O30 -> Yes | I30: ='Investment (capex)'!O30 -> No | J30: ='Wages salaries'!O30 -> No | K30: =COUNTIF(F30:J30,"yes") -> 3
A31: =A30+1 -> 30 | B31: Scan-Plast Latvia | C31: 22.24 | D31: https://www.scan-plast.com/lv/ | E31: - | F31: =Employees!O31 -> Yes | G31: ='Tangible assets'!O31 -> Yes | H31: ='Yearly Sales'!O31 -> Yes | I31: ='Investment (capex)'!O31 -> Yes | J31: ='Wages salaries'!O31 -> Yes | K31: =COUNTIF(F31:J31,"yes") -> 5
A32: =A31+1 -> 31 | B32: texmex | C32: NA | D32: NA | E32: This is either a type or some scheme idk, also it is the only one granted by the ministry of economics | F32: =Employees!O32 -> No | G32: ='Tangible assets'!O32 -> No | H32: ='Yearly Sales'!O32 -> No | I32: ='Investment (capex)'!O32 -> No | J32: ='Wages salaries'!O32 -> No | K32: =COUNTIF(F32:J32,"yes") -> 0
A33: =A32+1 -> 32 | B33: JELGAVAS TIPOGRĀFIJA | C33: 18.12 | D33: https://jt.lv/en/digital-printing/ | E33: - | F33: =Employees!O33 -> Yes | G33: ='Tangible assets'!O33 -> Yes | H33: ='Yearly Sales'!O33 -> Yes | I33: ='Investment (capex)'!O33 -> Yes | J33: ='Wages salaries'!O33 -> Yes | K33: =COUNTIF(F33:J33,"yes") -> 5
A34: =A33+1 -> 33 | B34: ICS Property | C34: 68.2 | D34: https://www.icsproperty.lv/ | E34: Either someone fucked up the registry or we have texmex publishing company | F34: =Employees!O34 -> No | G34: ='Tangible assets'!O34 -> No | H34: ='Yearly Sales'!O34 -> No | I34: ='Investment (capex)'!O34 -> No | J34: ='Wages salaries'!O34 -> No | K34: =COUNTIF(F34:J34,"yes") -> 0
A35: =A34+1 -> 34 | B35: VIZULO | C35: 27.4 | D35: https://www.vizulo.com/en | F35: =Employees!O35 -> Yes | G35: ='Tangible assets'!O35 -> IDK | H35: ='Yearly Sales'!O35 -> Yes | I35: ='Investment (capex)'!O35 -> Yes | J35: ='Wages salaries'!O35 -> Yes | K35: =COUNTIF(F35:J35,"yes") -> 4
E36: Total | F36: =COUNTIF(F2:F35,"yes") -> 24 | G36: =COUNTIF(G2:G35,"yes") -> 19 | H36: =COUNTIF(H2:H35,"yes") -> 23 | I36: =COUNTIF(I2:I35,"yes") -> 13 | J36: =COUNTIF(J2:J35,"yes") -> 19
I37: Totals | J37: 5 out of 5 | K37: =COUNTIF(K2:K35, "5") -> 11
J38: 4 out of 5 | K38: =COUNTIF(K2:K35, "4") -> 5
J39: 3 out of 5 | K39: =COUNTIF(K2:K35, "3") -> 3
J40: 2 out of 5 | K40: =COUNTIF(K2:K35, "2") -> 6
...

Sheet Non treated
A1: Nace code | B1: Name | C1: ID | D1: Notes
A2: 25.4 | B2: AMATEKS | C2: 40003576806
A3: 25.11 | B3: BELMAST | C3: 40003490550
A4: 10.51 | B4: Latvijas maiznieks | C4: 40003034051
A5: 68.2 | B5: LES TRANS | C5: 42103021051
A6: 23.99 | B6: CompositeLine | C6: 40003990979
A7: 20.3 | B7: AS BIOLARS | C7: 40003245470
A8: 25.11 | B8: RK Metāls | C8: 42103009504
A9: 43.22 | B9: VEKTRA-21 | C9: 42103011833
A10: 16.11 | B10: Gaujas Koks | C10: 40003037448
A11: 46.9 | B11: PLUTOS SELL | C11: 40103687559
A12: 19.2 | B12: Baltic new technologies | C12: 41203036919
A13: 41 | B13: AIMASA | C13: 44103032138
... A28: 16.21 | B28: Baltic Block SIA | C28: 40003332918

Sheet Employees
A1: Employees | B1: 2013 | C1: =B1+1 -> 2014 | D1: =C1+1 -> 2015 | E1: =D1+1 -> 2016 | F1: =E1+1 -> 2017 | G1: =F1+1 -> 2018 | H1: =G1+1 -> 2019 | I1: =H1+1 -> 2020 | J1: =I1+1 -> 2021 | ... N1: =M1+1 -> 2025 | O1: DATA FIT | P1: Notes
A2: ='Firm list'!B2 -> Mārupes Metālmeistars | B2: 80 | C2: 80 | D2: 80 | E2: 90 | F2: 96 | G2: 105 | H2: 105 | I2: 115 | J2: 117 | K2: 114 | L2: 75 | M2: 73 | N2: 75 | O2: Yes
A3: ='Firm list'!B3 -> TECNOPALI NORTH EUROPE | B3: 31 | C3: 33 | D3: 38 | E3: 37 | F3: 38 | G3: 44 | H3: 49 | I3: 58 | J3: 61 | K3: 59 | L3: 63 | M3: 63 | N3: NA | O3: Yes
A4: ='Firm list'!B4 -> Ventspils Brīvostas pārvalde | B4: NA | C4: NA | D4: NA | E4: NA | F4: NA | G4: 275 | H4: 269 | I4: 237 | J4: 212 | K4: 185 | L4: 178 | M4: 182 | N4: NA | O4: No
A5: ='Firm list'!B5 -> Tukuma Piens | B5: 245 | C5: 245 | D5: 249 | E5: 217 | F5: 205 | G5: 211 | H5: 209 | I5: 215 | J5: 220 | K5: 192 | L5: 215 | M5: 225 | N5: NA | O5: Yes
A6: ='Firm list'!B6 -> Vecās Ostmalas Biznesa Parks | B6: NA | C6: 0 | D6: 1 | E6: 2 | F6: 5 | G6: 5 | H6: 4 | I6: 4 | J6: 7 | K6: 6 | L6: 6 | M6: 5 | N6: 5 | O6: Yes | S6: T-2 | T6: T-1 | U6: T0 | V6: T1 | W6: T2 | X6: T3
A7: ='Firm list'!B7 -> TRAPI | B7: NA | C7: NA | D7: NA | E7: 0 | F7: 0 | G7: 2 | H7: 2 | I7: 2 | J7: 3 | K7: 3 | L7: 3 | M7: 3 | N7: 3 | O7: No | S7: 80 | T7: 80 | U7: 90 | V7: 96 | W7: 105 | X7: 105 | AF7: =X7-W7 -> 0
A8: ='Firm list'!B8 -> GP TEHNOPARKI | B8: NA | C8: NA | D8: NA | E8: 1 | F8: 5 | G8: 6 | H8: 6 | I8: 1 | J8: 1 | K8: 2 | L8: 2 | M8: 0 | N8: 0 | O8: No | S8: 33 | T8: 38 | U8: 37 | V8: 38 | W8: 44 | X8: 49
A9: ='Firm list'!B9 -> NTC INVESTĪCIJAS | B9: NA | C9: 0 | D9: 0 | E9: 0 | F9: 0 | G9: 0 | H9: 0 | I9: 0 | J9: 0 | K9: 0 | L9: 0 | M9: 1 | N9: 1 | O9: No | P9: Company was only founded in 2014 | S9: 245 | T9: 249 | U9: 217 | V9: 205 | W9: 211 | X9: 209
A10: ='Firm list'!B10 -> TENAX | B10: 18 | C10: 17 | D10: 17 | E10: 7 | F10: 7 | G10: 14 | H10: 15 | I10: 13 | J10: 14 | K10: 14 | L10: 13 | M10: 14 | N10: NA | O10: Yes | S10: 0 | T10: 1 | U10: 2 | V10: 5 | W10: 5 | X10: 4
A11: ='Firm list'!B11 -> IT INTERNATIONAL | B11: 22 | C11: 9 | D11: 8 | E11: 12 | F11: 7 | G11: 1 | H11: NA | I11: NA | J11: NA | K11: NA | L11: NA | M11: NA | N11: NA | O11: No | P11: Liquidated | S11: 17 | T11: 17 | U11: 7 | V11: 7 | W11: 14 | X11: 15
A12: ='Firm list'!B12 -> iCotton | B12: 37 | C12: 64 | D12: 109 | E12: 150 | F12: 149 | G12: 168 | H12: 127 | I12: 111 | J12: 143 | K12: 152 | L12: 158 | M12: 143 | N12: 140 | O12: Yes | S12: 109 | T12: 150 | U12: 149 | V12: 168 | W12: 127 | X12: 111
A13: ='Firm list'!B13 -> Lyngson | B13: 98 | C13: 105 | D13: 108 | E13: 107 | F13: 112 | G13: 133 | H13: 134 | I13: 130 | J13: 128 | K13: 128 | L13: 127 | M13: 114 | N13: NA | O13: Yes | S13: 108 | T13: 107 | U13: 112 | V13: 133 | W13: 134 | X13: 130
A14: ='Firm list'!B14 -> Piebalgas | B14: 79 | C14: 79 | D14: 70 | E14: 68 | F14: 66 | G14: 66 | H14: 63 | I14: 63 | J14: 63 | K14: 62 | L14: 57 | M14: 57 | N14: 56 | O14: Yes | S14: 70 | T14: 68 | U14: 66 | V14: 66 | W14: 63 | X14: 63
A15: ='Firm list'!B15 -> Kronus | B15: NA | C15: 249 | D15: 249 | E15: 249 | F15: 249 | G15: 249 | H15: 356 | I15: 435 | J15: 542 | K15: 538 | L15: 565 | M15: 522 | N15: NA | O15: Yes | S15: 249 | T15: 249 | U15: 249 | V15: 249 | W15: 356 | X15: 435
A16: ='Firm list'!B16 -> NPK Expert | B16: 5 | C16: 33 | D16: 35 | E16: 3 | F16: NA | G16: NA | H16: NA | I16: NA | J16: NA | K16: NA | L16: NA | M16: NA | N16: NA | O16: No | P16: Liquidated | S16: 4 | T16: 2 | U16: 3 | V16: 3 | W16: 4 | X16: 4
A17: ='Firm list'!B17 -> EcoLead | B17: 6 | C17: 6 | D17: 4 | E17: 2 | F17: 3 | G17: 3 | H17: 4 | I17: 4 | J17: 6 | K17: 9 | L17: 34 | M17: 44 | N17: NA | O17: Yes | S17: 3 | T17: 2 | U17: 1 | V17: 1 | W17: 6 | X17: 3
A18: ='Firm list'!B18 -> Carbon energy systems | B18: 1 | C18: 3 | D18: 3 | E18: 2 | F18: 1 | G18: 1 | H18: 6 | I18: 3 | J18: 3 | K18: 1 | L18: 2 | M18: 9 | N18: 10 | O18: Yes | S18: 205 | T18: 221 | U18: 229 | V18: 226 | W18: 243 | X18: 230
A19: ='Firm list'!B19 -> JĒKABPILS PMK | B19: 233 | C19: 260 | D19: 226 | E19: 186 | F19: 205 | G19: 221 | H19: 229 | I19: 226 | J19: 243 | K19: 230 | L19: 236 | M19: 210 | N19: NA | O19: Yes | S19: 67 | T19: 68 | U19: 75 | V19: 71 | W19: 68 | X19: 67
A20: ='Firm list'!B20 -> AmberBirch | B20: NA | C20: NA | D20: NA | E20: NA | F20: 1 | G20: 1 | H20: 14 | I20: 60 | J20: 77 | K20: 83 | L20: 85 | M20: 87 | N20: NA | O20: No | P20: Started operating in 2018 only | S20: 7 | T20: 7 | U20: 6 | V20: 6 | W20: 6 | X20: 6
A21: ='Firm list'!B21 -> VALMIERMUIŽAS ALUS | B21: 30 | C21: 41 | D21: 52 | E21: 63 | F21: 67 | G21: 68 | H21: 75 | I21: 71 | J21: 68 | K21: 67 | L21: 111 | M21: 120 | N21: 127 | O21: Yes | S21: 35 | T21: 60 | U21: 103 | V21: 96 | W21: 103 | X21: 108
A22: ='Firm list'!B22 -> PUMAC LIEPAJA | C22: 10 | D22: 8 | E22: 7 | F22: 7 | G22: 7 | H22: 6 | I22: 6 | J22: 6 | K22: 6 | L22: 6 | M22: 6 | N22: NA | O22: Yes | S22: 82 | T22: 98 | U22: 111 | V22: 104 | W22: 115 | X22: 135
A23: ='Firm list'!B23 -> CEWOOD | B23: 0 | C23: 0 | D23: 2 | E23: 24 | F23: 35 | G23: 60 | H23: 103 | I23: 96 | J23: 103 | K23: 108 | L23: 131 | M23: 155 | N23: NA | O23: Yes | S23: 153 | T23: 174 | U23: 209 | V23: 206 | W23: 213 | X23: 246
A24: ='Firm list'!B24 -> VUDLANDE | B24: 73 | C24: 74 | D24: 74 | E24: 74 | F24: 82 | G24: 98 | H24: 111 | I24: 104 | J24: 115 | K24: 135 | L24: 102 | M24: 108 | N24: 108 | O24: Yes | S24: 78 | T24: 83 | U24: 76 | V24: 73 | W24: 72 | X24: 64
A25: ='Firm list'!B25 -> Artex Latvia | B25: 59 | C25: 70 | D25: 86 | E25: 101 | F25: 153 | G25: 174 | H25: 209 | I25: 206 | J25: 213 | K25: 246 | L25: 277 | M25: 220 | N25: 192 | O25: Yes | S25: 238 | T25: 200 | U25: 222 | V25: 248 | W25: 304 | X25: 350
A26: ='Firm list'!B26 -> SFM Latvia | B26: 30 | C26: 29 | D26: 39 | E26: 52 | F26: 78 | G26: 83 | H26: 76 | I26: 73 | J26: 72 | K26: 64 | L26: 68 | M26: 75 | N26: 95 | O26: Yes | S26: 34 | T26: 57 | U26: 65 | V26: 88 | W26: 112 | X26: 93
A27: ='Firm list'!B27 -> EB Liepāja | B27: NA | C27: NA | D27: NA | E27: NA | F27: NA | G27: 0 | H27: 0 | I27: 0 | J27: 0 | K27: 0 | L27: 0 | M27: 0 | N27: 0 | O27: No | P27: 0 employee company | S27: 14 | T27: 18 | U27: 19 | V27: 24 | W27: 37 | X27: 45
A28: ='Firm list'!B28 -> Stiga RM | B28: 56 | C28: 67 | D28: 141 | E28: 99 | F28: 176 | G28: 238 | H28: 200 | I28: 222 | J28: 248 | K28: 304 | L28: 350 | M28: 409 | N28: NA | O28: Yes | S28: 64 | T28: 58 | U28: 61 | V28: 53 | W28: 52 | X28: 53
A29: ='Firm list'!B29 -> Haugaard Baltic | B29: 0 | C29: 0 | D29: 6 | E29: 12 | F29: 25 | G29: 34 | H29: 57 | I29: 65 | J29: 88 | K29: 112 | L29: 93 | M29: 96 | N29: 114 | O29: Yes | S29: 144 | T29: 163 | U29: 156 | V29: 177 | W29: 198 | X29: 197
A30: ='Firm list'!B30 -> IKTK | B30: 0 | C30: 1 | D30: 4 | E30: 5 | F30: 9 | G30: 14 | H30: 18 | I30: 19 | J30: 24 | K30: 37 | L30: 45 | M30: 49 | N30: 54 | O30: Yes | S30: 99 | T30: 114 | U30: 98 | V30: 117 | W30: 169 | X30: 154 | AB30: T-2 | AC30: T-1 | AD30: T0 | AE30: T1 | AF30: T2 | AG30: T3
A31: ='Firm list'!B31 -> Scan-Plast Latvia | B31: 80 | C31: 68 | D31: 72 | E31: 61 | F31: 63 | G31: 64 | H31: 58 | I31: 61 | J31: 53 | K31: 52 | L31: 53 | M31: 51 | N31: 51 | O31: Yes | R31: Total | S31: =SUM(S7:S30) -> 2138 | T31: =SUM(T7:T30) -> 2284 | U31: =SUM(U7:U30) -> 2363 | V31: =SUM(V7:V30) -> 2460 | W31: =SUM(W7:W30) -> 2761 | X31: =SUM(X7:X30) -> 2876 | AA31: Treated group | AB31: 2138 | AC31: 2284 | AD31: 2363 | AE31: 2460 | AF31: 2761 | AG31: 2876
A32: ='Firm list'!B32 -> texmex | B32: NA | C32: NA | D32: NA | E32: NA | F32: NA | G32: NA | H32: NA | I32: NA | J32: NA | K32: NA | L32: NA | M32: NA | N32: NA | O32: No | AA32: Control group | AB32: 2994 | AC32: 3110 | AD32: 3044 | AE32: 2941 | AF32: 2899 | AG32: 2786
A33: ='Firm list'!B33 -> JELGAVAS TIPOGRĀFIJA | B33: 112 | C33: 111 | D33: 124 | E33: 123 | F33: 129 | G33: 144 | H33: 163 | I33: 156 | J33: 177 | K33: 198 | L33: 197 | M33: 194 | N33: 197 | O33: Yes | AA33: Tr Diff | AE33: =(AE31-AD31)/AD31 -> 0.041049513 | AF33: =(AF31-AD31)/AD31 -> 0.16842996 | AG33: =(AG31-AD31)/AD31 -> 0.21709691
A34: ='Firm list'!B34 -> ICS Property | B34: NA | C34: NA | D34: NA | E34: NA | F34: NA | G34: NA | H34: 2 | I34: 2 | J34: 2 | K34: 2 | L34: 2 | M34: 2 | N34: 2 | O34: No | AA34: Con Diff | AE34: =(AE32-AD32)/AD32 -> -0.033837057 | AF34: =(AF32-AD32)/AD32 -> -0.047634691 | AG34: =(AG32-AD32)/AD32 -> -0.084756899
A35: ='Firm list'!B35 -> VIZULO | B35: 10 | C35: 20 | D35: 44 | E35: 45 | F35: 54 | G35: 73 | H35: 99 | I35: 114 | J35: 98 | K35: 117 | L35: 169 | M35: 154 | N35: NA | O35: Yes | AA35: Diff-in-Diff | AE35: =AE33-AE34 -> 0.07488657 | AF35: =AF33-AF34 -> 0.21606465 | AG35: =AG33-AG34 -> 0.30185381
AA36: Counterfactual treated group | AD36: 2363 | AE36: =AD31+AD31*AE34 -> 2283.043 | AF36: =AD31+AD31*AF34 -> 2250.4392 | AG36: =AD31+AD31*AG34 -> 2162.7194
N37: Total passing | O37: =COUNTIF(O2:O35,"yes") -> 24
A39: Emlpoyees | B39: 2013 | C39: =B39+1 -> 2014 | D39: =C39+1 -> 2015 | E39: =D39+1 -> 2016 | F39: =E39+1 -> 2017 | G39: =F39+1 -> 2018 | H39: =G39+1 -> 2019 | I39: =H39+1 -> 2020 | J39: =I39+1 -> 2021 | ... N39: =M39+1 -> 2025 | O39: DATA FIT | P39: Notes | S39: T-2 | T39: T-1 | U39: T0 | V39: T1 | W39: T2 | X39: T3
A40: BELMAST | C40: 226 | D40: 200 | E40: 168 | F40: 191 | G40: 189 | H40: 165 | S40: 226 | T40: 200 | U40: 168 | V40: 191 | W40: 189 | X40: 165
A41: AMATEKS | C41: 34 | D41: 37 | E41: 46 | F41: 49 | G41: 49 | H41: 43 | S41: 34 | T41: 37 | U41: 46 | V41: 49 | W41: 49 | X41: 43
...

Sheet Yearly Sales
A1: Neto apgrozījums | B1: 2013 | C1: =B1+1 -> 2014 | D1: =C1+1 -> 2015 | E1: =D1+1 -> 2016 | F1: =E1+1 -> 2017 | G1: =F1+1 -> 2018 | H1: =G1+1 -> 2019 | I1: =H1+1 -> 2020 | J1: =I1+1 -> 2021 | ... N1: =M1+1 -> 2025 | O1: DATA FIT | P1: Notes
A2: Mārupes Metālmeistars | B2: 5832316 | C2: 5820104 | D2: 6952182 | E2: 7055932 | F2: 9215175 | G2: 9996824 | H2: 11083959 | I2: 10664294 | J2: 15503276 | K2: 16995344 | L2: 11343302 | M2: 9912444 | N2: 9925685 | O2: Yes
A3: TECNOPALI NORTH EUROPE | B3: 1129652 | C3: 2142589 | D3: 3093690 | E3: 2945640 | F3: 3892376 | G3: 5409473 | H3: 5519360 | I3: 6756811 | J3: 8501770 | K3: 13744869 | L3: 11805053 | M3: 9730508 | N3: NA | O3: Yes
A4: Ventspils Brīvostas pārvalde | B4: 17308552 | C4: 24386907 | D4: 21605800 | E4: 20121407 | F4: 21229083 | G4: 21939952 | H4: 23243013 | I4: 15602202 | J4: 15281705 | K4: 19754888 | L4: 15082338 | M4: 17462498 | N4: 18221868 | O4: Yes
A5: Tukuma Piens | B5: 34659059 | C5: 53194916 | D5: 46910324 | E5: 46129720 | F5: 53186134 | G5: 55097643 | H5: 57894764 | I5: 66371774 | J5: 65790286 | K5: 76561185 | L5: 88904649 | M5: 94881767 | N5: NA | O5: Yes
A6: Vecās Ostmalas Biznesa Parks | B6: NA | C6: 0 | D6: 9037 | E6: 145617 | F6: 206622 | G6: 243656 | H6: 370145 | I6: 481693 | J6: 552571 | K6: 742267 | L6: 746750 | M6: 952020 | N6: 946205 | O6: No | P6: Just started this company, might get eschezed results
A7: TRAPI | B7: NA | C7: NA | D7: NA | E7: 0 | F7: 0 | G7: 228115 | H7: 31312 | I7: 10000 | J7: 0 | K7: 114369 | L7: 250422 | M7: 243041 | N7: 243041 | O7: No | S7: T-2 | T7: T-1 | U7: T0 | V7: T1 | W7: T2 | X7: T3
A8: GP TEHNOPARKI | B8: NA | C8: NA | D8: 0 | E8: 0 | F8: 171307 | G8: 325213 | H8: 127025 | I8: 0 | J8: 24439 | K8: 107901 | L8: 74708 | M8: 0 | N8: NA | O8: No | S8: 5820104 | T8: 6952182 | U8: 7055932 | V8: 9215175 | W8: 9996824 | X8: 11083959
A9: NTC INVESTĪCIJAS | B9: 0 | C9: 5573 | D9: 11994 | E9: 24195 | F9: 26928 | G9: 20795 | H9: 33540 | I9: 47925 | J9: 138102 | K9: 197464 | L9: 199946 | M9: 146105 | N9: 282741 | O9: Yes | S9: 2142589 | T9: 3093690 | U9: 2945640 | V9: 3892376 | W9: 5409473 | X9: 5519360
A10: TENAX | B10: 1272814 | C10: 1843543 | D10: 1626775 | E10: 743918 | F10: 829543 | G10: 1053967 | H10: 1641168 | I10: 1694616 | J10: 1879027 | K10: 1953241 | L10: 2289351 | M10: 2523326 | N10: NA | O10: Yes | S10: 24386907 | T10: 21605800 | U10: 20121407 | V10: 21229083 | W10: 21939952 | X10: 23243013
A11: IT INTERNATIONAL | B11: 748487 | C11: 1052571 | D11: 1821154 | E11: 1092818 | F11: 798995 | G11: 226251 | H11: NA | I11: NA | J11: NA | K11: NA | L11: NA | M11: NA | N11: NA | O11: No | P11: Liquidated | S11: 53194916 | T11: 46910324 | U11: 46129720 | V11: 53186134 | W11: 55097643 | X11: 57894764
A12: iCotton | B12: 619128 | C12: 5725894 | D12: 5763079 | E12: 9445222 | F12: 18695782 | G12: 25966495 | H12: 26273886 | I12: 28381032 | J12: 21658350 | K12: 19637448 | L12: 16159823 | M12: 12086459 | N12: 15689933 | O12: Yes | S12: 5573 | T12: 11994 | U12: 24195 | V12: 26928 | W12: 20795 | X12: 33540
A13: Lyngson | B13: 10639668 | C13: 11695598 | D13: 11053920 | E13: 10654491 | F13: 12435811 | G13: 13893616 | H13: 13518423 | I13: 12803242 | J13: 14738615 | K13: 18924058 | L13: 15619301 | M13: 11413608 | N13: NA | O13: Yes | S13: 1843543 | T13: 1626775 | U13: 743918 | V13: 829543 | W13: 1053967 | X13: 1641168
A14: Piebalgas | B14: 6166301 | C14: 7372334 | D14: 5604600 | E14: 5107709 | F14: 6042284 | G14: 6698241 | H14: 5487576 | I14: 6289412 | J14: 7055719 | K14: 9545132 | L14: 6933267 | M14: 7761623 | N14: 5798254 | O14: Yes | S14: 5763079 | T14: 9445222 | U14: 18695782 | V14: 25966495 | W14: 26273886 | X14: 28381032
A15: Kronus | B15: 27201561 | C15: 28035477 | D15: 28124373 | E15: 31388492 | F15: 39978056 | G15: 49109610 | H15: 41317816 | I15: 44435198 | J15: 87752342 | K15: 124736999 | L15: 92892077 | M15: 85969169 | N15: NA | O15: Yes | S15: 11053920 | T15: 10654491 | U15: 12435811 | V15: 13893616 | W15: 13518423 | X15: 12803242
A16: NPK Expert | B16: 2239475 | C16: 10160767 | D16: 15411195 | E16: 14833532 | F16: NA | G16: NA | H16: NA | I16: NA | J16: NA | K16: NA | L16: NA | M16: NA | N16: NA | O16: No | P16: Liquidated | S16: 5604600 | T16: 5107709 | U16: 6042284 | V16: 6698241 | W16: 5487576 | X16: 6289412
A17: EcoLead | B17: NA | C17: NA | D17: NA | E17: NA | F17: NA | G17: NA | H17: NA | I17: NA | J17: 74629 | K17: 180634 | L17: 4101929 | M17: 9777770 | N17: NA | O17: No | S17: 28124373 | T17: 31388492 | U17: 39978056 | V17: 49109610 | W17: 41317816 | X17: 44435198
A18: Carbon energy systems | B18: 0 | C18: 0 | D18: 0 | E18: 0 | F18: 0 | G18: 0 | H18: 0 | I18: 0 | J18: 0 | K18: 0 | L18: 0 | M18: 9040 | N18: 30117 | O18: No | P18: Zero sales | S18: 12483863 | T18: 14667191 | U18: 19698882 | V18: 19101679 | W18: 18073713 | X18: 21877095
A19: JĒKABPILS PMK | B19: 11332031 | C19: 14805701 | D19: 14239816 | E19: 5790706 | F19: 12483863 | G19: 14667191 | H19: 19698882 | I19: 19101679 | J19: 18073713 | K19: 21877095 | L19: 24232828 | M19: 17071487 | N19: NA | O19: Yes | S19: 4605931 | T19: 5372787 | U19: 5683824 | V19: 5517672 | W19: 5816047 | X19: 7016988
A20: AmberBirch | B20: NA | C20: NA | D20: NA | E20: NA | F20: 27907 | G20: 48332 | H20: 220236 | I20: 7420678 | J20: 12397598 | K20: 24001131 | L20: 26626401 | M20: 21647336 | N20: NA | O20: No | S20: 2228728 | T20: 2521113 | U20: 2681245 | V20: 2655026 | W20: 2631479 | X20: 2702046
A21: VALMIERMUIŽAS ALUS | B21: 1751693 | C21: 3387547 | D21: 3840233 | E21: 4226454 | F21: 4605931 | G21: 5372787 | H21: 5683824 | I21: 5517672 | J21: 5816047 | K21: 7016988 | L21: 9435322 | M21: 10018435 | N21: 10538765 | O21: Yes | S21: 1282637 | T21: 4272962 | U21: 6565998 | V21: 7537714 | W21: 10178101 | X21: 12945298
A22: PUMAC LIEPAJA | B22: 1529904 | C22: 1718895 | D22: 1887778 | E22: 2108053 | F22: 2228728 | G22: 2521113 | H22: 2681245 | I22: 2655026 | J22: 2631479 | K22: 2702046 | L22: 3238097 | M22: 3293954 | N22: NA | O22: Yes | S22: 14802416 | T22: 19344872 | U22: 22003118 | V22: 17393548 | W22: 44136749 | X22: 60877228
A23: CEWOOD | B23: 0 | C23: 0 | D23: 0 | E23: 422347 | F23: 1282637 | G23: 4272962 | H23: 6565998 | I23: 7537714 | J23: 10178101 | K23: 12945298 | L23: 14655944 | M23: 16449406 | N23: NA | O23: Yes | S23: 3484504 | T23: 4206259 | U23: 4670600 | V23: 3638136 | W23: 4557049 | X23: 6776697
A24: VUDLANDE | B24: 10689176 | C24: 11691990 | D24: 12760446 | E24: 12979124 | F24: 14802416 | G24: 19344872 | H24: 22003118 | I24: 17393548 | J24: 44136749 | K24: 60877228 | L24: 17603250 | M24: 21696229 | N24: 24291524 | O24: Yes | S24: 6047473 | T24: 5621652 | U24: 5537013 | V24: 5285319 | W24: 6943767 | X24: 10851636
A25: Artex Latvia | B25: 700882 | C25: 869449 | D25: 1396566 | E25: 2366918 | F25: 3484504 | G25: 4206259 | H25: 4670600 | I25: 3638136 | J25: 4557049 | K25: 6776697 | L25: 7428951 | M25: 8217987 | N25: 8632772 | O25: Yes | S25: 24177895 | T25: 20553989 | U25: 23918559 | V25: 43052077 | W25: 69161043 | X25: 76554323
A26: SFM Latvia | B26: 1520335 | C26: 1992739 | D26: 3065305 | E26: 5000487 | F26: 6047473 | G26: 5621652 | H26: 5537013 | I26: 5285319 | J26: 6943767 | K26: 10851636 | L26: 8192943 | M26: 10931159 | N26: 13132882 | O26: Yes | S26: 3097029 | T26: 5661379 | U26: 6427336 | V26: 12636456 | W26: 16456435 | X26: 12265731
A27: EB Liepāja | B27: NA | C27: NA | D27: NA | E27: NA | F27: NA | G27: 0 | H27: 0 | I27: 0 | J27: 0 | K27: 0 | L27: 34000 | M27: 360000 | N27: 360000 | O27: No | S27: 1187395 | T27: 1262077 | U27: 1301518 | V27: 2634776 | W27: 3423393 | X27: 5612526
A28: Stiga RM | B28: 8190870 | C28: 8968714 | D28: 9287255 | E28: 13549693 | F28: 16548536 | G28: 24177895 | H28: 20553989 | I28: 23918559 | J28: 43052077 | K28: 69161043 | L28: 76554323 | M28: 80058988 | N28: NA | O28: Yes | S28: 2737013 | T28: 3215495 | U28: 3688854 | V28: 3060795 | W28: 2762710 | X28: 4663818
A29: Haugaard Baltic | B29: 0 | C29: 0 | D29: 272556 | E29: 898183 | F29: 2008675 | G29: 3097029 | H29: 5661379 | I29: 6427336 | J29: 12636456 | K29: 16456435 | L29: 12265731 | M29: 11584163 | N29: 12967428 | O29: Yes | S29: 11444636 | T29: 11659953 | U29: 10569009 | V29: 14017593 | W29: 17827403 | X29: 17704991
A30: IKTK | B30: 0 | C30: 0 | D30: 486957 | E30: 314743 | F30: 550111 | G30: 1187395 | H30: 1262077 | I30: 1301518 | J30: 2634776 | K30: 3423393 | L30: 5612526 | M30: 5080492 | N30: 5925696 | O30: Yes | S30: 10012999 | T30: 12897734 | U30: 8891546 | V30: 10853349 | W30: 15742864 | X30: 14708042
A31: Scan-Plast Latvia | B31: 0 | C31: 2832111 | D31: 3363649 | E31: 2153098 | F31: 3273100 | G31: 2737013 | H31: 3215495 | I31: 3688854 | J31: 3060795 | K31: 2762710 | L31: 4663818 | M31: 4123429 | N31: 4409458 | O31: Yes
A32: texmex | B32: NA | C32: NA | D32: NA | E32: NA | F32: NA | G32: NA | H32: NA | I32: NA | J32: NA | K32: NA | L32: NA | M32: NA | N32: NA | O32: No | R32: Total | S32: =SUM(S8:S30) -> 235532123 | T32: =SUM(T8:T30) -> 248054142 | U32: =SUM(U8:U30) -> 275810247 | V32: =SUM(V8:V30) -> 331431341 | W32: =SUM(W8:W30) -> 397827108 | X32: =SUM(X8:X30) -> 445881107
A33: JELGAVAS TIPOGRĀFIJA | B33: 5637899 | C33: 7575491 | D33: 8664574 | E33: 9655161 | F33: 9814691 | G33: 11444636 | H33: 11659953 | I33: 10569009 | J33: 14017593 | K33: 17827403 | L33: 17704991 | M33: 17134906 | N33: 18314322 | O33: Yes | AB33: T-2 | AC33: T-1 | AD33: T0 | AE33: T1 | AF33: T2 | AG33: T3
A34: ICS Property | B34: NA | C34: NA | D34: NA | E34: NA | F34: NA | G34: NA | H34: 0 | I34: 0 | J34: 0 | K34: 0 | L34: 0 | M34: 176134 | N34: 176134 | O34: No | AA34: Treated group | AB34: =S32 -> 235532123 | AC34: =T32 -> 248054142 | AD34: =U32 -> 275810247 | AE34: =V32 -> 331431341 | AF34: =W32 -> 397827108 | AG34: =X32 -> 445881107
A35: VIZULO | B35: 199481 | C35: 2860662 | D35: 6069438 | E35: 2556235 | F35: 5503911 | G35: 8062834 | H35: 10012999 | I35: 12897734 | J35: 8891546 | K35: 10853349 | L35: 15742864 | M35: 14708042 | N35: NA | O35: Yes | AA35: Control group | AB35: =S67 -> 290124912 | AC35: =T67 -> 303060311 | AD35: =U67 -> 318995129 | AE35: =V67 -> 362532671 | AF35: =W67 -> 368802682 | AG35: =X67 -> 378379898
AA36: Tr Diff | AE36: =(AE34-AD34)/AD34 -> 0.20166435 | AF36: =(AF34-AD34)/AD34 -> 0.44239423 | AG36: =(AG34-AD34)/AD34 -> 0.6166227
N37: Total passing | O37: =COUNTIF(O2:O35,"yes") -> 23 | AA37: Con Diff | AE37: =(AE35-AD35)/AD35 -> 0.13648341 | AF37: =(AF35-AD35)/AD35 -> 0.15613891 | AG37: =(AG35-AD35)/AD35 -> 0.18616199
AA38: Diff-in-Diff | AE38: =AE36-AE37 -> 0.065180942 | AF38: =AF36-AF37 -> 0.28625531 | AG38: =AG36-AG37 -> 0.43046071
B39: 2013 | C39: =B39+1 -> 2014 | D39: =C39+1 -> 2015 | E39: =D39+1 -> 2016 | F39: =E39+1 -> 2017 | G39: =F39+1 -> 2018 | H39: =G39+1 -> 2019 | I39: =H39+1 -> 2020 | J39: =I39+1 -> 2021 | ... N39: =M39+1 -> 2025 | AA39: Counterfactual treated group | AD39: 275810247 | AE39: =AD34+AD34*AE37 -> 3.1345377e+08 | AF39: =AD34+AD34*AF37 -> 3.1887496e+08 | AG39: =AD34+AD34*AG37 -> 3.2715563e+08
A40: BELMAST | C40: 9179681 | D40: 7353872 | E40: 7786052 | F40: 8995022 | G40: 8351746 | H40: 11643196
...

Sheet Investment (capex)
A1: Pamatlīdzekļu un nemateriālo ieguldījumu iegāde | B1: 2013 | C1: =B1+1 -> 2014 | D1: =C1+1 -> 2015 | E1: =D1+1 -> 2016 | F1: =E1+1 -> 2017 | G1: =F1+1 -> 2018 | H1: =G1+1 -> 2019 | I1: =H1+1 -> 2020 | J1: =I1+1 -> 2021 | ... N1: =M1+1 -> 2025 | O1: DATA FIT | P1: Notes
A2: Mārupes Metālmeistars | B2: 208947 | C2: -1204130 | D2: -1866881 | E2: -584561 | F2: -500917 | G2: -428275 | H2: -130080 | I2: -73852 | J2: -528266 | K2: -879762 | L2: -818767 | M2: -525339 | N2: -825026 | O2: Yes
A3: TECNOPALI NORTH EUROPE | B3: -31162 | C3: -302334 | D3: -196678 | E3: NA | F3: NA | G3: NA | H3: -151774 | I3: -318539 | J3: -507376 | K3: -412218 | L3: -398215 | M3: -3506903 | N3: NA | O3: No
A4: Ventspils Brīvostas pārvalde | B4: -19229191 | C4: NA | D4: NA | E4: NA | F4: NA | G4: -20870755 | H4: -21337630 | I4: -6391471 | J4: -3003604 | K4: -3927398 | L4: -9468935 | M4: -3721279 | N4: -2112381 | O4: No
A5: Tukuma Piens | B5: -2836636 | C5: -2178797 | D5: -1603849 | E5: -3198365 | F5: -2602981 | G5: -2305741 | H5: -7235548 | I5: -4747020 | J5: -1039595 | K5: -486127 | L5: -2669876 | M5: -6300366 | N5: NA | O5: Yes
A6: Vecās Ostmalas Biznesa Parks | B6: NA | C6: NA | D6: NA | E6: NA | F6: NA | G6: NA | H6: NA | I6: NA | J6: NA | K6: NA | L6: NA | M6: NA | N6: NA | O6: No | S6: T-2 | T6: T-1 | U6: T0 | V6: T1 | W6: T2 | X6: T3
A7: TRAPI | B7: NA | C7: NA | D7: NA | E7: NA | F7: NA | G7: NA | H7: NA | I7: NA | J7: NA | K7: NA | L7: NA | M7: NA | N7: NA | O7: No | S7: 1204130 | T7: 1866881 | U7: 584561 | V7: 500917 | W7: 428275 | X7: 130080
A8: GP TEHNOPARKI | B8: NA | C8: NA | D8: NA | E8: NA | F8: NA | G8: NA | H8: NA | I8: NA | J8: NA | K8: NA | L8: NA | M8: NA | N8: NA | O8: No | S8: 2178797 | T8: 1603849 | U8: 3198365 | V8: 2602981 | W8: 2305741 | X8: 7235548
A9: NTC INVESTĪCIJAS | B9: NA | C9: NA | D9: NA | E9: NA | F9: NA | G9: NA | H9: NA | I9: NA | J9: NA | K9: NA | L9: NA | M9: NA | N9: NA | O9: No | S9: 8631697 | T9: 668353 | U9: 694074 | V9: 2614693 | W9: 4258609 | X9: 8476925
A10: TENAX | B10: 589920 | C10: -207356 | D10: -610060 | E10: -142271 | F10: -429404 | G10: -609009 | H10: -594680 | I10: -816925 | J10: -83175 | K10: -6423429 | L10: -594803 | M10: -77132 | N10: NA | O10: Yes | S10: 85580 | T10: 1830314 | U10: 1737524 | V10: 1671437 | W10: 470762 | X10: 511136
A11: IT INTERNATIONAL | B11: -53530 | C11: NA | D11: NA | E11: NA | F11: NA | G11: NA | H11: NA | I11: NA | J11: NA | K11: NA | L11: NA | M11: NA | N11: NA | O11: No | P11: Liquidated | S11: 845734 | T11: 2390968 | U11: 2770758 | V11: 1960177 | W11: 1818664 | X11: 706522
A12: iCotton | B12: -1059775 | C12: -202782 | D12: -8631697 | E12: -668353 | F12: -694074 | G12: -2614693 | H12: -4258609 | I12: -8476925 | J12: -5160228 | K12: -1774292 | L12: -1027298 | M12: -284287 | N12: -233604 | O12: Yes | S12: 886122 | T12: 465145 | U12: 926858 | V12: 1695600 | W12: 220385 | X12: 270442
A13: Lyngson | B13: -532832 | C13: -334174 | D13: -85580 | E13: -1830314 | F13: -1737524 | G13: -1671437 | H13: -470762 | I13: -511136 | J13: -334659 | K13: -283242 | L13: -232340 | M13: -317491 | N13: NA | O13: Yes | S13: 615976 | T13: 565719 | U13: 155711 | V13: 115629 | W13: 317090 | X13: 951104
A14: Piebalgas | B14: -170450 | C14: NA | D14: NA | E14: NA | F14: NA | G14: NA | H14: NA | I14: NA | J14: NA | K14: -58223 | L14: -88041 | M14: NA | N14: NA | O14: No | S14: 694254 | T14: 1859123 | U14: 3752044 | V14: 2564153 | W14: 2298728 | X14: 5089609
A15: Kronus | B15: NA | C15: NA | D15: -845734 | E15: -2390968 | F15: -2770758 | G15: -1960177 | H15: -1818664 | I15: -706522 | J15: -1407853 | K15: -4327471 | L15: -3464524 | M15: -804655 | N15: NA | O15: Yes | S15: 9256829 | T15: 6279069 | U15: 11154747 | V15: 4581057 | W15: 19957951 | X15: 28721635
A16: NPK Expert | B16: -32631 | C16: -118259 | D16: NA | E16: NA | F16: NA | G16: NA | H16: NA | I16: NA | J16: NA | K16: NA | L16: NA | M16: NA | N16: NA | O16: No | P16: Liquidated | S16: 36500 | T16: 77762 | U16: 410425 | V16: 214614 | W16: 284027 | X16: 118466
A17: EcoLead | B17: NA | C17: NA | D17: NA | E17: NA | F17: NA | G17: NA | H17: NA | I17: NA | J17: NA | K17: NA | L17: NA | M17: NA | N17: NA | O17: No | S17: 384671 | T17: 796205 | U17: 2311256 | V17: 1205432 | W17: 156125 | X17: 866605
A18: Carbon energy systems | B18: NA | C18: NA | D18: NA | E18: NA | F18: NA | G18: NA | H18: NA | I18: NA | J18: NA | K18: NA | L18: NA | M18: NA | N18: NA | O18: No | S18: 931719 | T18: 889401 | U18: 603234 | V18: 522808 | W18: 2114029 | X18: 2245446
A19: JĒKABPILS PMK | B19: -81165 | C19: -151478 | D19: -68345 | E19: -83611 | F19: -886122 | G19: -465145 | H19: -926858 | I19: -1695600 | J19: -220385 | K19: -270442 | L19: -154089 | M19: -21317 | N19: NA | O19: Yes
A20: AmberBirch | B20: NA | C20: NA | D20: NA | E20: NA | F20: NA | G20: NA | H20: NA | I20: -217435 | J20: -907520 | K20: -710188 | L20: -2827778 | M20: -21591040 | N20: NA | O20: No
A21: VALMIERMUIŽAS ALUS | B21: -559884 | C21: -858128 | D21: -466806 | E21: -299209 | F21: -615976 | G21: -565719 | H21: -155711 | I21: -115629 | J21: -317090 | K21: -951104 | L21: -306655 | M21: -1000400 | N21: -819474 | O21: Yes
A22: PUMAC LIEPAJA | B22: NA | C22: NA | D22: NA | E22: NA | F22: NA | G22: NA | H22: NA | I22: NA | J22: NA | K22: NA | L22: NA | M22: NA | N22: NA | O22: No
A23: CEWOOD | B23: NA | C23: NA | D23: NA | E23: NA | F23: NA | G23: NA | H23: -605614 | I23: -408265 | J23: -1583552 | K23: -7937831 | L23: -4554152 | M23: -5768347 | N23: NA | O23: No
A24: VUDLANDE | B24: NA | C24: -448193 | D24: -446004 | E24: -412864 | F24: -694254 | G24: -1859123 | H24: -3752044 | I24: -2564153 | J24: -2298728 | K24: -5089609 | L24: -6486869 | M24: -6399059 | N24: -3086890 | O24: Yes
A25: Artex Latvia | B25: -2659 | C25: -267955 | D25: -13871 | E25: NA | F25: NA | G25: NA | H25: NA | I25: NA | J25: NA | K25: NA | L25: -201738 | M25: -367817 | N25: -27761 | O25: No
A26: SFM Latvia | B26: -15756 | C26: -2017 | D26: -929301 | E26: NA | F26: NA | G26: NA | H26: NA | I26: NA | J26: NA | K26: -3641942 | L26: -900568 | M26: -1346395 | N26: -1398765 | O26: No
A27: EB Liepāja | B27: NA | C27: NA | D27: NA | E27: NA | F27: NA | G27: NA | H27: NA | I27: NA | J27: NA | K27: NA | L27: NA | M27: NA | N27: NA | O27: No
A28: Stiga RM | B28: -1405376 | C28: -2754322 | D28: -4765085 | E28: -1351776 | F28: -506149 | G28: -9256829 | H28: -6279069 | I28: -11154747 | J28: -4581057 | K28: -19957951 | L28: -28721635 | M28: -36286841 | N28: NA | O28: Yes
A29: Haugaard Baltic | B29: 0 | C29: 0 | D29: -16462 | E29: -39565 | F29: NA | G29: NA | H29: NA | I29: -49774 | J29: -151985 | K29: -108831 | L29: -409519 | M29: -230601 | N29: -428126 | O29: No | AA29: T-2 | AB29: T-1 | AC29: T0 | AD29: T1 | AE29: T2 | AF29: T3
A30: IKTK | B30: NA | C30: NA | D30: NA | E30: NA | F30: NA | G30: NA | H30: NA | I30: NA | J30: NA | K30: NA | L30: NA | M30: NA | N30: NA | O30: No | Z30: Treated group | AA30: =SUM(S7:S18) -> 25752009 | AB30: =SUM(T7:T18) -> 19292789 | AC30: =SUM(U7:U18) -> 28299557 | AD30: =SUM(V7:V18) -> 20249498 | AE30: =SUM(W7:W18) -> 34630386 | AF30: =SUM(X7:X18) -> 55323518
A31: Scan-Plast Latvia | B31: NA | C31: -29131 | D31: -287231 | E31: -65014 | F31: -55968 | G31: -36500 | H31: -77762 | I31: -410425 | J31: -214614 | K31: -284027 | L31: -118466 | M31: -238123 | N31: -118912 | O31: Yes | Z31: Control group | AA31: =SUM(S43:S53) -> 14957102 | AB31: =SUM(T43:T53) -> 16395041 | AC31: =SUM(U43:U53) -> 15613353 | AD31: =SUM(V43:V53) -> 28496274 | AE31: =SUM(W43:W53) -> 37975733 | AF31: =SUM(X43:X53) -> 57077729
A32: texmex | B32: NA | C32: NA | D32: NA | E32: NA | F32: NA | G32: NA | H32: NA | I32: NA | J32: NA | K32: NA | L32: NA | M32: NA | N32: NA | O32: No | Z32: Tr Diff | AD32: =(AD30-$AC$30)/$AC$30 -> -0.28445883 | AE32: =(AE30-$AC$30)/$AC$30 -> 0.22370771 | AF32: =(AF30-$AC$30)/$AC$30 -> 0.95492523
A33: JELGAVAS TIPOGRĀFIJA | B33: -283456 | C33: -2455264 | D33: -453463 | E33: -135721 | F33: -252518 | G33: -384671 | H33: -796205 | I33: -2311256 | J33: -1205432 | K33: -156125 | L33: -866605 | M33: -1097993 | N33: -2258310 | O33: Yes | Z33: Con Diff | AD33: =(AD31-$AC$31)/$AC$31 -> 0.825122 | AE33: =(AE31-$AC$31)/$AC$31 -> 1.4322599 | AF33: =(AF31-$AC$31)/$AC$31 -> 2.6556996
